# All the exception has been moved.
# See errors.py
